Workbook

Sheet Config
A1: Farmley Run Rate Dashboard
A3: Parameter | B3: Value | C3: Type
A4: Days in Month | B4: 30 | C4: EDITABLE ↕
A5: SO Date From | B5: 2026-05-01 | C5: Auto
A6: SO Date To | B6: 2026-05-19 | C6: Auto
A7: Days Elapsed (1st to max SO date) | B7: 19 | C7: Auto
A8: Projection File | B8: May 2026 Sales Projection (5).xlsx | C8: Info
A9: Sales Order File | B9: Custom Sales Order Report (40).xlsx | C9: Info
A10: Generated | B10: 2026-05-21 06:14 | C10: Info
A11: SO Rows Raw / Clean | B11: 23129 / 23042 | C11: Info
A12: Output Rows | B12: 2109 | C12: Info
A15: Color Legend
A16: >120% | B16: Urgent procurement
A17: 100-120% | B17: Plan procurement
A18: 80-100% | B18: On watch
A19: 50-80% | B19: Comfortable
A20: <50% | B20: No pressure
A21: 0% | B21: No orders
A23: Change B4 (Days in Month) → all formula cells recalculate automatically
A24: Expand/collapse grouped rows using [+]/[-] buttons on left margin

Sheet RunRate by Item Name
A1: Month | B1: Year | C1: Last Modified Date | D1: Last Modified Time | E1: Item Code | F1: BOM Item Type | G1: Item Group | H1: Item Name | I1: Item Parent | J1: Conversion Factor | K1: Projection Units | L1: Customer | M1: Total KGs | N1: Customer Group | O1: Origin | P1: Item Type | Q1: New MIS Item Group | R1: Daily Demand(Total KGs) | S1: Daily Demand(Projection Units) | T1: Projected KGs as of period | U1: Projected Units as of period | V1: Actual SO KGs | W1: Actual SO Units | X1: Achievement % KGs | Y1: Achievement % Units | Z1: Diff Proj-SO KGs | AA1: Diff Proj-SO Units | AB1: Run Rate Month-End KGs | AC1: Run Rate Month-End Units
A2: May | B2: 2026 | C2: 29-04-2026 | D2: 0.47064815 | E2: Makhana_7-30163 | F2: FG | G2: Roasted & Flavoured Makhana | H2: Roasted & Flavored Makhana - Tangy Tomato Farmley Composite Jar 83 g | I2: Prasadam Roasted Makhana | J2: 0.083 | K2: 5129 | L2: 3 Customers | M2: 425.71 | N2: Multiple | O2: Purnea | P2: Value Added | Q2: Roasted & Flavoured Makhana | R2: =IF(Config!$B$4>0,M2/Config!$B$4,0) | S2: =IF(Config!$B$4>0,K2/Config!$B$4,0) | T2: =R2*Config!$B$7 | U2: =S2*Config!$B$7 | V2: 35.86 | W2: 432 | X2: =IF(T2>0,V2/T2,0) | Y2: =IF(U2>0,W2/U2,0) | Z2: =T2-V2 | AA2: =U2-W2 | AB2: =IF(Config!$B$7>0,(V2/Config!$B$7)*Config!$B$4,0) | AC2: =IF(Config!$B$7>0,(W2/Config!$B$7)*Config!$B$4,0)
A3: May | B3: 2026 | C3: 29-04-2026 | D3: 0.47064815 | E3: Makhana_7-30163 | F3: FG | G3: Roasted & Flavoured Makhana | H3: Roasted & Flavored Makhana - Tangy Tomato Farmley Composite Jar 83 g | I3: Prasadam Roasted Makhana | J3: 0.083 | K3: 2904 | L3: Canteen Store Department (CSD) | M3: 241.03 | N3: CSD | O3: Purnea | P3: Value Added | Q3: Roasted & Flavoured Makhana | R3: =IF(Config!$B$4>0,M3/Config!$B$4,0) | S3: =IF(Config!$B$4>0,K3/Config!$B$4,0) | T3: =R3*Config!$B$7 | U3: =S3*Config!$B$7 | V3: 0 | W3: 0 | X3: =IF(T3>0,V3/T3,0) | Y3: =IF(U3>0,W3/U3,0) | Z3: =T3-V3 | AA3: =U3-W3 | AB3: =IF(Config!$B$7>0,(V3/Config!$B$7)*Config!$B$4,0) | AC3: =IF(Config!$B$7>0,(W3/Config!$B$7)*Config!$B$4,0)
A4: May | B4: 2026 | C4: 30-04-2026 | D4: 0.69038194 | E4: Makhana_7-30163 | F4: FG | G4: Roasted & Flavoured Makhana | H4: Roasted & Flavored Makhana - Tangy Tomato Farmley Composite Jar 83 g | I4: Prasadam Roasted Makhana | J4: 0.083 | K4: 1225 | L4: Amazon Retail India Private Limited | M4: 101.67 | N4: Amazon Retail India | O4: Purnea | P4: Value Added | Q4: Roasted & Flavoured Makhana | R4: =IF(Config!$B$4>0,M4/Config!$B$4,0) | S4: =IF(Config!$B$4>0,K4/Config!$B$4,0) | T4: =R4*Config!$B$7 | U4: =S4*Config!$B$7 | V4: 0 | W4: 0 | X4: =IF(T4>0,V4/T4,0) | Y4: =IF(U4>0,W4/U4,0) | Z4: =T4-V4 | AA4: =U4-W4 | AB4: =IF(Config!$B$7>0,(V4/Config!$B$7)*Config!$B$4,0) | AC4: =IF(Config!$B$7>0,(W4/Config!$B$7)*Config!$B$4,0)
A5: May | B5: 2026 | C5: 25-04-2026 | D5: 0.62569444 | E5: Makhana_7-30163 | F5: FG | G5: Roasted & Flavoured Makhana | H5: Roasted & Flavored Makhana - Tangy Tomato Farmley Composite Jar 83 g | I5: Prasadam Roasted Makhana | J5: 0.083 | K5: 1000 | L5: Avenue E-Commerce Ltd | M5: 83 | N5: E-Commerce | O5: Purnea | P5: Value Added | Q5: Roasted & Flavoured Makhana | R5: =IF(Config!$B$4>0,M5/Config!$B$4,0) | S5: =IF(Config!$B$4>0,K5/Config!$B$4,0) | T5: =R5*Config!$B$7 | U5: =S5*Config!$B$7 | V5: 35.86 | W5: 432 | X5: =IF(T5>0,V5/T5,0) | Y5: =IF(U5>0,W5/U5,0) | Z5: =T5-V5 | AA5: =U5-W5 | AB5: =IF(Config!$B$7>0,(V5/Config!$B$7)*Config!$B$4,0) | AC5: =IF(Config!$B$7>0,(W5/Config!$B$7)*Config!$B$4,0)
A6: May | B6: 2026 | C6: 29-04-2026 | D6: 0.47065972 | E6: Makhana_7-30166 | F6: FG | G6: Roasted & Flavoured Makhana | H6: Roasted & Flavored Makhana - Mint Farmley Composite Jar 83 g | I6: Prasadam Roasted Makhana | J6: 0.083 | K6: 5329 | L6: 4 Customers | M6: 442.31 | N6: Multiple | O6: Purnea | P6: Value Added | Q6: Roasted & Flavoured Makhana | R6: =IF(Config!$B$4>0,M6/Config!$B$4,0) | S6: =IF(Config!$B$4>0,K6/Config!$B$4,0) | T6: =R6*Config!$B$7 | U6: =S6*Config!$B$7 | V6: 39.84 | W6: 480 | X6: =IF(T6>0,V6/T6,0) | Y6: =IF(U6>0,W6/U6,0) | Z6: =T6-V6 | AA6: =U6-W6 | AB6: =IF(Config!$B$7>0,(V6/Config!$B$7)*Config!$B$4,0) | AC6: =IF(Config!$B$7>0,(W6/Config!$B$7)*Config!$B$4,0)
A7: May | B7: 2026 | C7: 29-04-2026 | D7: 0.47065972 | E7: Makhana_7-30166 | F7: FG | G7: Roasted & Flavoured Makhana | H7: Roasted & Flavored Makhana - Mint Farmley Composite Jar 83 g | I7: Prasadam Roasted Makhana | J7: 0.083 | K7: 2736 | L7: Canteen Store Department (CSD) | M7: 227.09 | N7: CSD | O7: Purnea | P7: Value Added | Q7: Roasted & Flavoured Makhana | R7: =IF(Config!$B$4>0,M7/Config!$B$4,0) | S7: =IF(Config!$B$4>0,K7/Config!$B$4,0) | T7: =R7*Config!$B$7 | U7: =S7*Config!$B$7 | V7: 0 | W7: 0 | X7: =IF(T7>0,V7/T7,0) | Y7: =IF(U7>0,W7/U7,0) | Z7: =T7-V7 | AA7: =U7-W7 | AB7: =IF(Config!$B$7>0,(V7/Config!$B$7)*Config!$B$4,0) | AC7: =IF(Config!$B$7>0,(W7/Config!$B$7)*Config!$B$4,0)
A8: May | B8: 2026 | C8: 30-04-2026 | D8: 0.69038194 | E8: Makhana_7-30166 | F8: FG | G8: Roasted & Flavoured Makhana | H8: Roasted & Flavored Makhana - Mint Farmley Composite Jar 83 g | I8: Prasadam Roasted Makhana | J8: 0.083 | K8: 1281 | L8: Amazon Retail India Private Limited | M8: 106.32 | N8: Amazon Retail India | O8: Purnea | P8: Value Added | Q8: Roasted & Flavoured Makhana | R8: =IF(Config!$B$4>0,M8/Config!$B$4,0) | S8: =IF(Config!$B$4>0,K8/Config!$B$4,0) | T8: =R8*Config!$B$7 | U8: =S8*Config!$B$7 | V8: 0 | W8: 0 | X8: =IF(T8>0,V8/T8,0) | Y8: =IF(U8>0,W8/U8,0) | Z8: =T8-V8 | AA8: =U8-W8 | AB8: =IF(Config!$B$7>0,(V8/Config!$B$7)*Config!$B$4,0) | AC8: =IF(Config!$B$7>0,(W8/Config!$B$7)*Config!$B$4,0)
A9: May | B9: 2026 | C9: 25-04-2026 | D9: 0.62569444 | E9: Makhana_7-30166 | F9: FG | G9: Roasted & Flavoured Makhana | H9: Roasted & Flavored Makhana - Mint Farmley Composite Jar 83 g | I9: Prasadam Roasted Makhana | J9: 0.083 | K9: 1000 | L9: Avenue E-Commerce Ltd | M9: 83 | N9: E-Commerce | O9: Purnea | P9: Value Added | Q9: Roasted & Flavoured Makhana | R9: =IF(Config!$B$4>0,M9/Config!$B$4,0) | S9: =IF(Config!$B$4>0,K9/Config!$B$4,0) | T9: =R9*Config!$B$7 | U9: =S9*Config!$B$7 | V9: 35.86 | W9: 432 | X9: =IF(T9>0,V9/T9,0) | Y9: =IF(U9>0,W9/U9,0) | Z9: =T9-V9 | AA9: =U9-W9 | AB9: =IF(Config!$B$7>0,(V9/Config!$B$7)*Config!$B$4,0) | AC9: =IF(Config!$B$7>0,(W9/Config!$B$7)*Config!$B$4,0)
A10: May | B10: 2026 | C10: 25-04-2026 | D10: 0.72665509 | E10: Makhana_7-30166 | F10: FG | G10: Roasted & Flavoured Makhana | H10: Roasted & Flavored Makhana - Mint Farmley Composite Jar 83 g | I10: Prasadam Roasted Makhana | J10: 0.083 | K10: 312 | L10: Avenue Supermarts Ltd | M10: 25.9 | N10: Modern Trade | O10: Purnea | P10: Value Added | Q10: Roasted & Flavoured Makhana | R10: =IF(Config!$B$4>0,M10/Config!$B$4,0) | S10: =IF(Config!$B$4>0,K10/Config!$B$4,0) | T10: =R10*Config!$B$7 | U10: =S10*Config!$B$7 | V10: 3.98 | W10: 48 | X10: =IF(T10>0,V10/T10,0) | Y10: =IF(U10>0,W10/U10,0) | Z10: =T10-V10 | AA10: =U10-W10 | AB10: =IF(Config!$B$7>0,(V10/Config!$B$7)*Config!$B$4,0) | AC10: =IF(Config!$B$7>0,(W10/Config!$B$7)*Config!$B$4,0)
A11: May | B11: 2026 | C11: 29-04-2026 | D11: 0.47065972 | E11: Makhana_7-30167 | F11: FG | G11: Roasted & Flavoured Makhana | H11: Roasted & Salted Makhana Farmley Composite Jar 83 g | I11: Prasadam Roasted Makhana | J11: 0.083 | K11: 9105 | L11: 4 Customers | M11: 755.72 | N11: Multiple | O11: Purnea | P11: Value Added | Q11: Roasted & Flavoured Makhana | R11: =IF(Config!$B$4>0,M11/Config!$B$4,0) | S11: =IF(Config!$B$4>0,K11/Config!$B$4,0) | T11: =R11*Config!$B$7 | U11: =S11*Config!$B$7 | V11: 93.62 | W11: 1128 | X11: =IF(T11>0,V11/T11,0) | Y11: =IF(U11>0,W11/U11,0) | Z11: =T11-V11 | AA11: =U11-W11 | AB11: =IF(Config!$B$7>0,(V11/Config!$B$7)*Config!$B$4,0) | AC11: =IF(Config!$B$7>0,(W11/Config!$B$7)*Config!$B$4,0)
A12: May | B12: 2026 | C12: 29-04-2026 | D12: 0.47065972 | E12: Makhana_7-30167 | F12: FG | G12: Roasted & Flavoured Makhana | H12: Roasted & Salted Makhana Farmley Composite Jar 83 g | I12: Prasadam Roasted Makhana | J12: 0.083 | K12: 2448 | L12: Canteen Store Department (CSD) | M12: 203.18 | N12: CSD | O12: Purnea | P12: Value Added | Q12: Roasted & Flavoured Makhana | R12: =IF(Config!$B$4>0,M12/Config!$B$4,0) | S12: =IF(Config!$B$4>0,K12/Config!$B$4,0) | T12: =R12*Config!$B$7 | U12: =S12*Config!$B$7 | V12: 0 | W12: 0 | X12: =IF(T12>0,V12/T12,0) | Y12: =IF(U12>0,W12/U12,0) | Z12: =T12-V12 | AA12: =U12-W12 | AB12: =IF(Config!$B$7>0,(V12/Config!$B$7)*Config!$B$4,0) | AC12: =IF(Config!$B$7>0,(W12/Config!$B$7)*Config!$B$4,0)
A13: May | B13: 2026 | C13: 30-04-2026 | D13: 0.69040509 | E13: Makhana_7-30167 | F13: FG | G13: Roasted & Flavoured Makhana | H13: Roasted & Salted Makhana Farmley Composite Jar 83 g | I13: Prasadam Roasted Makhana | J13: 0.083 | K13: 4545 | L13: Amazon Retail India Private Limited | M13: 377.24 | N13: Amazon Retail India | O13: Purnea | P13: Value Added | Q13: Roasted & Flavoured Makhana | R13: =IF(Config!$B$4>0,M13/Config!$B$4,0) | S13: =IF(Config!$B$4>0,K13/Config!$B$4,0) | T13: =R13*Config!$B$7 | U13: =S13*Config!$B$7 | V13: 0 | W13: 0 | X13: =IF(T13>0,V13/T13,0) | Y13: =IF(U13>0,W13/U13,0) | Z13: =T13-V13 | AA13: =U13-W13 | AB13: =IF(Config!$B$7>0,(V13/Config!$B$7)*Config!$B$4,0) | AC13: =IF(Config!$B$7>0,(W13/Config!$B$7)*Config!$B$4,0)
... A30: May | B30: 2026 | C30: 25-04-2026 | D30: 0.7266088 | E30: Cashewnut_3-1987 | F30: FG | G30: Cashew | H30: Premium W320 Cashew Farmley Standee Pouch 500 g | I30: Premium W320 Cashew | J30: 0.5 | K30: 100 | L30: Wal-Mart India Private Limited | M30: 50 | N30: Modern Trade | O30: Udupi | P30: KVI | Q30: Cashew | R30: =IF(Config!$B$4>0,M30/Config!$B$4,0) | S30: =IF(Config!$B$4>0,K30/Config!$B$4,0) | T30: =R30*Config!$B$7 | U30: =S30*Config!$B$7 | V30: 100 | W30: 200 | X30: =IF(T30>0,V30/T30,0) | Y30: =IF(U30>0,W30/U30,0) | Z30: =T30-V30 | AA30: =U30-W30 | AB30: =IF(Config!$B$7>0,(V30/Config!$B$7)*Config!$B$4,0) | AC30: =IF(Config!$B$7>0,(W30/Config!$B$7)*Config!$B$4,0)
E31: Cashewnut_3-1987 | G31: Cashewnut | H31: Premium W320 Cashew Farmley Standee Pouch 500 g | J31: 0 | K31: 0 | L31: CPC - C P C Master Canteen -Khargone -Madhya Pradesh -451115 | M31: 0 | N31: CPC KPKB | O31: Udupi | Q31: Cashew | R31: =IF(Config!$B$4>0,M31/Config!$B$4,0) | S31: =IF(Config!$B$4>0,K31/Config!$B$4,0) | T31: =R31*Config!$B$7 | U31: =S31*Config!$B$7 | V31: 30 | W31: 60 | X31: =IF(T31>0,V31/T31,0) | Y31: =IF(U31>0,W31/U31,0) | Z31: =T31-V31 | AA31: =U31-W31 | AB31: =IF(Config!$B$7>0,(V31/Config!$B$7)*Config!$B$4,0) | AC31: =IF(Config!$B$7>0,(W31/Config!$B$7)*Config!$B$4,0)
E32: Cashewnut_3-1987 | G32: Cashewnut | H32: Premium W320 Cashew Farmley Standee Pouch 500 g | J32: 0 | K32: 0 | L32: CPC - Canteen Officer Master Canteen Frontier HQR SSB Lucknow | M32: 0 | N32: CPC KPKB | O32: Udupi | Q32: Cashew | R32: =IF(Config!$B$4>0,M32/Config!$B$4,0) | S32: =IF(Config!$B$4>0,K32/Config!$B$4,0) | T32: =R32*Config!$B$7 | U32: =S32*Config!$B$7 | V32: 32 | W32: 64 | X32: =IF(T32>0,V32/T32,0) | Y32: =IF(U32>0,W32/U32,0) | Z32: =T32-V32 | AA32: =U32-W32 | AB32: =IF(Config!$B$7>0,(V32/Config!$B$7)*Config!$B$4,0) | AC32: =IF(Config!$B$7>0,(W32/Config!$B$7)*Config!$B$4,0)
E33: Cashewnut_3-1987 | G33: Cashewnut | H33: Premium W320 Cashew Farmley Standee Pouch 500 g | J33: 0 | K33: 0 | L33: CPC - Central Police Canteen Cisf Unit Kopt Kolkata | M33: 0 | N33: CPC KPKB | O33: Udupi | Q33: Cashew | R33: =IF(Config!$B$4>0,M33/Config!$B$4,0) | S33: =IF(Config!$B$4>0,K33/Config!$B$4,0) | T33: =R33*Config!$B$7 | U33: =S33*Config!$B$7 | V33: 190 | W33: 380 | X33: =IF(T33>0,V33/T33,0) | Y33: =IF(U33>0,W33/U33,0) | Z33: =T33-V33 | AA33: =U33-W33 | AB33: =IF(Config!$B$7>0,(V33/Config!$B$7)*Config!$B$4,0) | AC33: =IF(Config!$B$7>0,(W33/Config!$B$7)*Config!$B$4,0)
E34: Cashewnut_3-1987 | G34: Cashewnut | H34: Premium W320 Cashew Farmley Standee Pouch 500 g | J34: 0 | K34: 0 | L34: CPC - Commandant 57th Bn SSB | M34: 0 | N34: CPC KPKB | O34: Udupi | Q34: Cashew | R34: =IF(Config!$B$4>0,M34/Config!$B$4,0) | S34: =IF(Config!$B$4>0,K34/Config!$B$4,0) | T34: =R34*Config!$B$7 | U34: =S34*Config!$B$7 | V34: 200 | W34: 400 | X34: =IF(T34>0,V34/T34,0) | Y34: =IF(U34>0,W34/U34,0) | Z34: =T34-V34 | AA34: =U34-W34 | AB34: =IF(Config!$B$7>0,(V34/Config!$B$7)*Config!$B$4,0) | AC34: =IF(Config!$B$7>0,(W34/Config!$B$7)*Config!$B$4,0)
E35: Cashewnut_3-1987 | G35: Cashewnut | H35: Premium W320 Cashew Farmley Standee Pouch 500 g | J35: 0 | K35: 0 | L35: CPC - KPKB Master Canteen Dhanbad | M35: 0 | N35: CPC KPKB | O35: Udupi | Q35: Cashew | R35: =IF(Config!$B$4>0,M35/Config!$B$4,0) | S35: =IF(Config!$B$4>0,K35/Config!$B$4,0) | T35: =R35*Config!$B$7 | U35: =S35*Config!$B$7 | V35: 200 | W35: 400 | X35: =IF(T35>0,V35/T35,0) | Y35: =IF(U35>0,W35/U35,0) | Z35: =T35-V35 | AA35: =U35-W35 | AB35: =IF(Config!$B$7>0,(V35/Config!$B$7)*Config!$B$4,0) | AC35: =IF(Config!$B$7>0,(W35/Config!$B$7)*Config!$B$4,0)
E36: Cashewnut_3-1987 | G36: Cashewnut | H36: Premium W320 Cashew Farmley Standee Pouch 500 g | J36: 0 | K36: 0 | L36: CPC - Kendriya Police Kalyan Bhandar - HP | M36: 0 | N36: CPC KPKB | O36: Udupi | Q36: Cashew | R36: =IF(Config!$B$4>0,M36/Config!$B$4,0) | S36: =IF(Config!$B$4>0,K36/Config!$B$4,0) | T36: =R36*Config!$B$7 | U36: =S36*Config!$B$7 | V36: 100 | W36: 200 | X36: =IF(T36>0,V36/T36,0) | Y36: =IF(U36>0,W36/U36,0) | Z36: =T36-V36 | AA36: =U36-W36 | AB36: =IF(Config!$B$7>0,(V36/Config!$B$7)*Config!$B$4,0) | AC36: =IF(Config!$B$7>0,(W36/Config!$B$7)*Config!$B$4,0)
E37: Cashewnut_3-1987 | G37: Cashewnut | H37: Premium W320 Cashew Farmley Standee Pouch 500 g | J37: 0 | K37: 0 | L37: CPC - Kendriya Police Kalyan Master Bhandar | M37: 0 | N37: CPC KPKB | O37: Udupi | Q37: Cashew | R37: =IF(Config!$B$4>0,M37/Config!$B$4,0) | S37: =IF(Config!$B$4>0,K37/Config!$B$4,0) | T37: =R37*Config!$B$7 | U37: =S37*Config!$B$7 | V37: 30 | W37: 60 | X37: =IF(T37>0,V37/T37,0) | Y37: =IF(U37>0,W37/U37,0) | Z37: =T37-V37 | AA37: =U37-W37 | AB37: =IF(Config!$B$7>0,(V37/Config!$B$7)*Config!$B$4,0) | AC37: =IF(Config!$B$7>0,(W37/Config!$B$7)*Config!$B$4,0)
E38: Cashewnut_3-1987 | G38: Cashewnut | H38: Premium W320 Cashew Farmley Standee Pouch 500 g | J38: 0 | K38: 0 | L38: CPC - Master Bhandar | M38: 0 | N38: CPC KPKB | O38: Udupi | Q38: Cashew | R38: =IF(Config!$B$4>0,M38/Config!$B$4,0) | S38: =IF(Config!$B$4>0,K38/Config!$B$4,0) | T38: =R38*Config!$B$7 | U38: =S38*Config!$B$7 | V38: 60 | W38: 120 | X38: =IF(T38>0,V38/T38,0) | Y38: =IF(U38>0,W38/U38,0) | Z38: =T38-V38 | AA38: =U38-W38 | AB38: =IF(Config!$B$7>0,(V38/Config!$B$7)*Config!$B$4,0) | AC38: =IF(Config!$B$7>0,(W38/Config!$B$7)*Config!$B$4,0)
E39: Cashewnut_3-1987 | G39: Cashewnut | H39: Premium W320 Cashew Farmley Standee Pouch 500 g | J39: 0 | K39: 0 | L39: CPC - Master Bhandar - Haryana | M39: 0 | N39: CPC KPKB | O39: Udupi | Q39: Cashew | R39: =IF(Config!$B$4>0,M39/Config!$B$4,0) | S39: =IF(Config!$B$4>0,K39/Config!$B$4,0) | T39: =R39*Config!$B$7 | U39: =S39*Config!$B$7 | V39: 30 | W39: 60 | X39: =IF(T39>0,V39/T39,0) | Y39: =IF(U39>0,W39/U39,0) | Z39: =T39-V39 | AA39: =U39-W39 | AB39: =IF(Config!$B$7>0,(V39/Config!$B$7)*Config!$B$4,0) | AC39: =IF(Config!$B$7>0,(W39/Config!$B$7)*Config!$B$4,0)
E40: Cashewnut_3-1987 | G40: Cashewnut | H40: Premium W320 Cashew Farmley Standee Pouch 500 g | J40: 0 | K40: 0 | L40: CPC - Master Bhandar CRPF HQ CGO | M40: 0 | N40: CPC KPKB | O40: Udupi | Q40: Cashew | R40: =IF(Config!$B$4>0,M40/Config!$B$4,0) | S40: =IF(Config!$B$4>0,K40/Config!$B$4,0) | T40: =R40*Config!$B$7 | U40: =S40*Config!$B$7 | V40: 130 | W40: 260 | X40: =IF(T40>0,V40/T40,0) | Y40: =IF(U40>0,W40/U40,0) | Z40: =T40-V40 | AA40: =U40-W40 | AB40: =IF(Config!$B$7>0,(V40/Config!$B$7)*Config!$B$4,0) | AC40: =IF(Config!$B$7>0,(W40/Config!$B$7)*Config!$B$4,0)
E41: Cashewnut_3-1987 | G41: Cashewnut | H41: Premium W320 Cashew Farmley Standee Pouch 500 g | J41: 0 | K41: 0 | L41: CPC - Master Bhandar Kendriya Police Kalyan Bhandar | M41: 0 | N41: CPC KPKB | O41: Udupi | Q41: Cashew | R41: =IF(Config!$B$4>0,M41/Config!$B$4,0) | S41: =IF(Config!$B$4>0,K41/Config!$B$4,0) | T41: =R41*Config!$B$7 | U41: =S41*Config!$B$7 | V41: 20 | W41: 40 | X41: =IF(T41>0,V41/T41,0) | Y41: =IF(U41>0,W41/U41,0) | Z41: =T41-V41 | AA41: =U41-W41 | AB41: =IF(Config!$B$7>0,(V41/Config!$B$7)*Config!$B$4,0) | AC41: =IF(Config!$B$7>0,(W41/Config!$B$7)*Config!$B$4,0)
E42: Cashewnut_3-1987 | G42: Cashewnut | H42: Premium W320 Cashew Farmley Standee Pouch 500 g | J42: 0 | K42: 0 | L42: CPC - Master Bhander Gc-1 CRPF Ajmer | M42: 0 | N42: CPC KPKB | O42: Udupi | Q42: Cashew | R42: =IF(Config!$B$4>0,M42/Config!$B$4,0) | S42: =IF(Config!$B$4>0,K42/Config!$B$4,0) | T42: =R42*Config!$B$7 | U42: =S42*Config!$B$7 | V42: 150 | W42: 300 | X42: =IF(T42>0,V42/T42,0) | Y42: =IF(U42>0,W42/U42,0) | Z42: =T42-V42 | AA42: =U42-W42 | AB42: =IF(Config!$B$7>0,(V42/Config!$B$7)*Config!$B$4,0) | AC42: =IF(Config!$B$7>0,(W42/Config!$B$7)*Config!$B$4,0)
... E72: Cashewnut_3-1987 | G72: Cashewnut | H72: Premium W320 Cashew Farmley Standee Pouch 500 g | J72: 0 | K72: 0 | L72: PJTJ Technologies Private Limited | M72: 0 | N72: Quick Commerce | O72: Udupi | Q72: Cashew | R72: =IF(Config!$B$4>0,M72/Config!$B$4,0) | S72: =IF(Config!$B$4>0,K72/Config!$B$4,0) | T72: =R72*Config!$B$7 | U72: =S72*Config!$B$7 | V72: 30 | W72: 60 | X72: =IF(T72>0,V72/T72,0) | Y72: =IF(U72>0,W72/U72,0) | Z72: =T72-V72 | AA72: =U72-W72 | AB72: =IF(Config!$B$7>0,(V72/Config!$B$7)*Config!$B$4,0) | AC72: =IF(Config!$B$7>0,(W72/Config!$B$7)*Config!$B$4,0)
A73: May | B73: 2026 | C73: 29-04-2026 | D73: 0.47065972 | E73: Seeds_11-2541 | F73: FG | G73: Chia Seeds | H73: Premium Chia Seeds Farmley Standee Pouch 200 g | I73: Premium Chia Seeds | J73: 0.2 | K73: 182029.61 | L73: 47 Customers | M73: 36405.92 | N73: Multiple | O73: Indore | P73: KVI | Q73: Chia Seeds | R73: =IF(Config!$B$4>0,M73/Config!$B$4,0) | S73: =IF(Config!$B$4>0,K73/Config!$B$4,0) | T73: =R73*Config!$B$7 | U73: =S73*Config!$B$7 | V73: 21282 | W73: 106410 | X73: =IF(T73>0,V73/T73,0) | Y73: =IF(U73>0,W73/U73,0) | Z73: =T73-V73 | AA73: =U73-W73 | AB73: =IF(Config!$B$7>0,(V73/Config!$B$7)*Config!$B$4,0) | AC73: =IF(Config!$B$7>0,(W73/Config!$B$7)*Config!$B$4,0)
A74: May | B74: 2026 | C74: 29-04-2026 | D74: 0.47065972 | E74: Seeds_11-2541 | F74: FG | G74: Chia Seeds | H74: Premium Chia Seeds Farmley Standee Pouch 200 g | I74: Premium Chia Seeds | J74: 0.2 | K74: 1740 | L74: Canteen Store Department (CSD) | M74: 348 | N74: CSD | O74: Indore | P74: KVI | Q74: Chia Seeds | R74: =IF(Config!$B$4>0,M74/Config!$B$4,0) | S74: =IF(Config!$B$4>0,K74/Config!$B$4,0) | T74: =R74*Config!$B$7 | U74: =S74*Config!$B$7 | V74: 0 | W74: 0 | X74: =IF(T74>0,V74/T74,0) | Y74: =IF(U74>0,W74/U74,0) | Z74: =T74-V74 | AA74: =U74-W74 | AB74: =IF(Config!$B$7>0,(V74/Config!$B$7)*Config!$B$4,0) | AC74: =IF(Config!$B$7>0,(W74/Config!$B$7)*Config!$B$4,0)
A75: May | B75: 2026 | C75: 29-04-2026 | D75: 0.4706713 | E75: Seeds_11-2541 | F75: FG | G75: Chia Seeds | H75: Premium Chia Seeds Farmley Standee Pouch 200 g | I75: Premium Chia Seeds | J75: 0.2 | K75: 3000 | L75: CPC KPKB | M75: 600 | N75: CPC | O75: Indore | P75: KVI | Q75: Chia Seeds | R75: =IF(Config!$B$4>0,M75/Config!$B$4,0) | S75: =IF(Config!$B$4>0,K75/Config!$B$4,0) | T75: =R75*Config!$B$7 | U75: =S75*Config!$B$7 | V75: 0 | W75: 0 | X75: =IF(T75>0,V75/T75,0) | Y75: =IF(U75>0,W75/U75,0) | Z75: =T75-V75 | AA75: =U75-W75 | AB75: =IF(Config!$B$7>0,(V75/Config!$B$7)*Config!$B$4,0) | AC75: =IF(Config!$B$7>0,(W75/Config!$B$7)*Config!$B$4,0)
A76: May | B76: 2026 | C76: 29-04-2026 | D76: 0.53008102 | E76: Seeds_11-2541 | F76: FG | G76: Chia Seeds | H76: Premium Chia Seeds Farmley Standee Pouch 200 g | I76: Premium Chia Seeds | J76: 0.2 | K76: 4000 | L76: Metro Cash & Carry India Private Limited | M76: 800 | N76: Modern Trade | O76: Indore | P76: KVI | Q76: Chia Seeds | R76: =IF(Config!$B$4>0,M76/Config!$B$4,0) | S76: =IF(Config!$B$4>0,K76/Config!$B$4,0) | T76: =R76*Config!$B$7 | U76: =S76*Config!$B$7 | V76: 390 | W76: 1950 | X76: =IF(T76>0,V76/T76,0) | Y76: =IF(U76>0,W76/U76,0) | Z76: =T76-V76 | AA76: =U76-W76 | AB76: =IF(Config!$B$7>0,(V76/Config!$B$7)*Config!$B$4,0) | AC76: =IF(Config!$B$7>0,(W76/Config!$B$7)*Config!$B$4,0)
A77: May | B77: 2026 | C77: 29-04-2026 | D77: 0.62038194 | E77: Seeds_11-2541 | F77: FG | G77: Chia Seeds | H77: Premium Chia Seeds Farmley Standee Pouch 200 g | I77: Premium Chia Seeds | J77: 0.2 | K77: 16330 | L77: Amazon Retail India Private Limited | M77: 3266 | N77: Amazon Retail India | O77: Indore | P77: KVI | Q77: Chia Seeds | R77: =IF(Config!$B$4>0,M77/Config!$B$4,0) | S77: =IF(Config!$B$4>0,K77/Config!$B$4,0) | T77: =R77*Config!$B$7 | U77: =S77*Config!$B$7 | V77: 2370 | W77: 11850 | X77: =IF(T77>0,V77/T77,0) | Y77: =IF(U77>0,W77/U77,0) | Z77: =T77-V77 | AA77: =U77-W77 | AB77: =IF(Config!$B$7>0,(V77/Config!$B$7)*Config!$B$4,0) | AC77: =IF(Config!$B$7>0,(W77/Config!$B$7)*Config!$B$4,0)
A78: May | B78: 2026 | C78: 29-04-2026 | D78: 0.68864583 | E78: Seeds_11-2541 | F78: FG | G78: Chia Seeds | H78: Premium Chia Seeds Farmley Standee Pouch 200 g | I78: Premium Chia Seeds | J78: 0.2 | K78: 574.61 | L78: Farmley Website B2C | M78: 114.92 | N78: Own Website | O78: Indore | P78: KVI | Q78: Chia Seeds | R78: =IF(Config!$B$4>0,M78/Config!$B$4,0) | S78: =IF(Config!$B$4>0,K78/Config!$B$4,0) | T78: =R78*Config!$B$7 | U78: =S78*Config!$B$7 | V78: 0 | W78: 0 | X78: =IF(T78>0,V78/T78,0) | Y78: =IF(U78>0,W78/U78,0) | Z78: =T78-V78 | AA78: =U78-W78 | AB78: =IF(Config!$B$7>0,(V78/Config!$B$7)*Config!$B$4,0) | AC78: =IF(Config!$B$7>0,(W78/Config!$B$7)*Config!$B$4,0)
A79: May | B79: 2026 | C79: 27-04-2026 | D79: 0.83001157 | E79: Seeds_11-2541 | F79: FG | G79: Chia Seeds | H79: Premium Chia Seeds Farmley Standee Pouch 200 g | I79: Premium Chia Seeds | J79: 0.2 | K79: 7000 | L79: GT Retail | M79: 1400 | N79: Category A | O79: Indore | P79: KVI | Q79: Chia Seeds | R79: =IF(Config!$B$4>0,M79/Config!$B$4,0) | S79: =IF(Config!$B$4>0,K79/Config!$B$4,0) | T79: =R79*Config!$B$7 | U79: =S79*Config!$B$7 | V79: 780 | W79: 3900 | X79: =IF(T79>0,V79/T79,0) | Y79: =IF(U79>0,W79/U79,0) | Z79: =T79-V79 | AA79: =U79-W79 | AB79: =IF(Config!$B$7>0,(V79/Config!$B$7)*Config!$B$4,0) | AC79: =IF(Config!$B$7>0,(W79/Config!$B$7)*Config!$B$4,0)
A80: May | B80: 2026 | C80: 25-04-2026 | D80: 0.59434028 | E80: Seeds_11-2541 | F80: FG | G80: Chia Seeds | H80: Premium Chia Seeds Farmley Standee Pouch 200 g | I80: Premium Chia Seeds | J80: 0.2 | K80: 19000 | L80: Flipkart India Private Limited | M80: 3800 | N80: E-Commerce | O80: Indore | P80: KVI | Q80: Chia Seeds | R80: =IF(Config!$B$4>0,M80/Config!$B$4,0) | S80: =IF(Config!$B$4>0,K80/Config!$B$4,0) | T80: =R80*Config!$B$7 | U80: =S80*Config!$B$7 | V80: 4068 | W80: 20340 | X80: =IF(T80>0,V80/T80,0) | Y80: =IF(U80>0,W80/U80,0) | Z80: =T80-V80 | AA80: =U80-W80 | AB80: =IF(Config!$B$7>0,(V80/Config!$B$7)*Config!$B$4,0) | AC80: =IF(Config!$B$7>0,(W80/Config!$B$7)*Config!$B$4,0)
A81: May | B81: 2026 | C81: 25-04-2026 | D81: 0.62571759 | E81: Seeds_11-2541 | F81: FG | G81: Chia Seeds | H81: Premium Chia Seeds Farmley Standee Pouch 200 g | I81: Premium Chia Seeds | J81: 0.2 | K81: 2500 | L81: Avenue E-Commerce Ltd | M81: 500 | N81: E-Commerce | O81: Indore | P81: KVI | Q81: Chia Seeds | R81: =IF(Config!$B$4>0,M81/Config!$B$4,0) | S81: =IF(Config!$B$4>0,K81/Config!$B$4,0) | T81: =R81*Config!$B$7 | U81: =S81*Config!$B$7 | V81: 108 | W81: 540 | X81: =IF(T81>0,V81/T81,0) | Y81: =IF(U81>0,W81/U81,0) | Z81: =T81-V81 | AA81: =U81-W81 | AB81: =IF(Config!$B$7>0,(V81/Config!$B$7)*Config!$B$4,0) | AC81: =IF(Config!$B$7>0,(W81/Config!$B$7)*Config!$B$4,0)
A82: May | B82: 2026 | C82: 25-04-2026 | D82: 0.63921296 | E82: Seeds_11-2541 | F82: FG | G82: Chia Seeds | H82: Premium Chia Seeds Farmley Standee Pouch 200 g | I82: Premium Chia Seeds | J82: 0.2 | K82: 8200 | L82: Flipkart B2C | M82: 1640 | N82: E-Commerce Dropship | O82: Indore | P82: KVI | Q82: Chia Seeds | R82: =IF(Config!$B$4>0,M82/Config!$B$4,0) | S82: =IF(Config!$B$4>0,K82/Config!$B$4,0) | T82: =R82*Config!$B$7 | U82: =S82*Config!$B$7 | V82: 0 | W82: 0 | X82: =IF(T82>0,V82/T82,0) | Y82: =IF(U82>0,W82/U82,0) | Z82: =T82-V82 | AA82: =U82-W82 | AB82: =IF(Config!$B$7>0,(V82/Config!$B$7)*Config!$B$4,0) | AC82: =IF(Config!$B$7>0,(W82/Config!$B$7)*Config!$B$4,0)
A83: May | B83: 2026 | C83: 25-04-2026 | D83: 0.6449537 | E83: Seeds_11-2541 | F83: FG | G83: Chia Seeds | H83: Premium Chia Seeds Farmley Standee Pouch 200 g | I83: Premium Chia Seeds | J83: 0.2 | K83: 2500 | L83: INNOVATIVE RETAIL CONCEPTS PRIVATE LIMITED | M83: 500 | N83: Quick Commerce | O83: Indore | P83: KVI | Q83: Chia Seeds | R83: =IF(Config!$B$4>0,M83/Config!$B$4,0) | S83: =IF(Config!$B$4>0,K83/Config!$B$4,0) | T83: =R83*Config!$B$7 | U83: =S83*Config!$B$7 | V83: 480 | W83: 2400 | X83: =IF(T83>0,V83/T83,0) | Y83: =IF(U83>0,W83/U83,0) | Z83: =T83-V83 | AA83: =U83-W83 | AB83: =IF(Config!$B$7>0,(V83/Config!$B$7)*Config!$B$4,0) | AC83: =IF(Config!$B$7>0,(W83/Config!$B$7)*Config!$B$4,0)
A84: May | B84: 2026 | C84: 25-04-2026 | D84: 0.65229167 | E84: Seeds_11-2541 | F84: FG | G84: Chia Seeds | H84: Premium Chia Seeds Farmley Standee Pouch 200 g | I84: Premium Chia Seeds | J84: 0.2 | K84: 1600 | L84: Reliance Retail Limited _Milk Basket | M84: 320 | N84: Quick Commerce | O84: Indore | P84: KVI | Q84: Chia Seeds | R84: =IF(Config!$B$4>0,M84/Config!$B$4,0) | S84: =IF(Config!$B$4>0,K84/Config!$B$4,0) | T84: =R84*Config!$B$7 | U84: =S84*Config!$B$7 | V84: 114 | W84: 570 | X84: =IF(T84>0,V84/T84,0) | Y84: =IF(U84>0,W84/U84,0) | Z84: =T84-V84 | AA84: =U84-W84 | AB84: =IF(Config!$B$7>0,(V84/Config!$B$7)*Config!$B$4,0) | AC84: =IF(Config!$B$7>0,(W84/Config!$B$7)*Config!$B$4,0)
... A93: May | B93: 2026 | C93: 25-04-2026 | D93: 0.72672454 | E93: Seeds_11-2541 | F93: FG | G93: Chia Seeds | H93: Premium Chia Seeds Farmley Standee Pouch 200 g | I93: Premium Chia Seeds | J93: 0.2 | K93: 180 | L93: Natures Basket Limited | M93: 36 | N93: Modern Trade | O93: Indore | P93: KVI | Q93: Chia Seeds | R93: =IF(Config!$B$4>0,M93/Config!$B$4,0) | S93: =IF(Config!$B$4>0,K93/Config!$B$4,0) | T93: =R93*Config!$B$7 | U93: =S93*Config!$B$7 | V93: 0 | W93: 0 | X93: =IF(T93>0,V93/T93,0) | Y93: =IF(U93>0,W93/U93,0) | Z93: =T93-V93 | AA93: =U93-W93 | AB93: =IF(Config!$B$7>0,(V93/Config!$B$7)*Config!$B$4,0) | AC93: =IF(Config!$B$7>0,(W93/Config!$B$7)*Config!$B$4,0)
...

Sheet RunRate by Cust Group
A1: Month | B1: Year | C1: Last Modified Date | D1: Last Modified Time | E1: Item Code | F1: BOM Item Type | G1: Item Group | H1: Item Name | I1: Item Parent | J1: Conversion Factor | K1: Projection Units | L1: Customer | M1: Total KGs | N1: Customer Group | O1: Origin | P1: Item Type | Q1: New MIS Item Group | R1: Daily Demand(Total KGs) | S1: Daily Demand(Projection Units) | T1: Projected KGs as of period | U1: Projected Units as of period | V1: Actual SO KGs | W1: Actual SO Units | X1: Achievement % KGs | Y1: Achievement % Units | Z1: Diff Proj-SO KGs | AA1: Diff Proj-SO Units | AB1: Run Rate Month-End KGs | AC1: Run Rate Month-End Units
A2: May | B2: 2026 | C2: 29-04-2026 | D2: 0.47064815 | E2: Multiple | F2: FG | G2: Roasted & Flavoured Makhana | H2: CSD | I2: Prasadam Roasted Makhana | J2: 0.083 | K2: 11418 | L2: Canteen Store Department (CSD) | M2: 1273.7 | N2: CSD | O2: Multiple | P2: Value Added | Q2: Roasted & Flavoured Makhana | R2: =IF(Config!$B$4>0,M2/Config!$B$4,0) | S2: =IF(Config!$B$4>0,K2/Config!$B$4,0) | T2: =R2*Config!$B$7 | U2: =S2*Config!$B$7 | V2: 0 | W2: 0 | X2: =IF(T2>0,V2/T2,0) | Y2: =IF(U2>0,W2/U2,0) | Z2: =T2-V2 | AA2: =U2-W2 | AB2: =IF(Config!$B$7>0,(V2/Config!$B$7)*Config!$B$4,0) | AC2: =IF(Config!$B$7>0,(W2/Config!$B$7)*Config!$B$4,0)
A3: May | B3: 2026 | C3: 29-04-2026 | D3: 0.47064815 | E3: Makhana_7-30163 | F3: FG | G3: Roasted & Flavoured Makhana | H3: Roasted & Flavored Makhana - Tangy Tomato Farmley Composite Jar 83 g | I3: Prasadam Roasted Makhana | J3: 0.083 | K3: 2904 | L3: Canteen Store Department (CSD) | M3: 241.03 | N3: CSD | O3: Purnea | P3: Value Added | Q3: Roasted & Flavoured Makhana | R3: =IF(Config!$B$4>0,M3/Config!$B$4,0) | S3: =IF(Config!$B$4>0,K3/Config!$B$4,0) | T3: =R3*Config!$B$7 | U3: =S3*Config!$B$7 | V3: 0 | W3: 0 | X3: =IF(T3>0,V3/T3,0) | Y3: =IF(U3>0,W3/U3,0) | Z3: =T3-V3 | AA3: =U3-W3 | AB3: =IF(Config!$B$7>0,(V3/Config!$B$7)*Config!$B$4,0) | AC3: =IF(Config!$B$7>0,(W3/Config!$B$7)*Config!$B$4,0)
A4: May | B4: 2026 | C4: 29-04-2026 | D4: 0.47065972 | E4: Makhana_7-30166 | F4: FG | G4: Roasted & Flavoured Makhana | H4: Roasted & Flavored Makhana - Mint Farmley Composite Jar 83 g | I4: Prasadam Roasted Makhana | J4: 0.083 | K4: 2736 | L4: Canteen Store Department (CSD) | M4: 227.09 | N4: CSD | O4: Purnea | P4: Value Added | Q4: Roasted & Flavoured Makhana | R4: =IF(Config!$B$4>0,M4/Config!$B$4,0) | S4: =IF(Config!$B$4>0,K4/Config!$B$4,0) | T4: =R4*Config!$B$7 | U4: =S4*Config!$B$7 | V4: 0 | W4: 0 | X4: =IF(T4>0,V4/T4,0) | Y4: =IF(U4>0,W4/U4,0) | Z4: =T4-V4 | AA4: =U4-W4 | AB4: =IF(Config!$B$7>0,(V4/Config!$B$7)*Config!$B$4,0) | AC4: =IF(Config!$B$7>0,(W4/Config!$B$7)*Config!$B$4,0)
A5: May | B5: 2026 | C5: 29-04-2026 | D5: 0.47065972 | E5: Makhana_7-30167 | F5: FG | G5: Roasted & Flavoured Makhana | H5: Roasted & Salted Makhana Farmley Composite Jar 83 g | I5: Prasadam Roasted Makhana | J5: 0.083 | K5: 2448 | L5: Canteen Store Department (CSD) | M5: 203.18 | N5: CSD | O5: Purnea | P5: Value Added | Q5: Roasted & Flavoured Makhana | R5: =IF(Config!$B$4>0,M5/Config!$B$4,0) | S5: =IF(Config!$B$4>0,K5/Config!$B$4,0) | T5: =R5*Config!$B$7 | U5: =S5*Config!$B$7 | V5: 0 | W5: 0 | X5: =IF(T5>0,V5/T5,0) | Y5: =IF(U5>0,W5/U5,0) | Z5: =T5-V5 | AA5: =U5-W5 | AB5: =IF(Config!$B$7>0,(V5/Config!$B$7)*Config!$B$4,0) | AC5: =IF(Config!$B$7>0,(W5/Config!$B$7)*Config!$B$4,0)
A6: May | B6: 2026 | C6: 29-04-2026 | D6: 0.47065972 | E6: Dry Fruit Mix_15-2941 | F6: FG | G6: Seed Mix | H6: Seed mix Farmley 160g Standee Pouches | I6: Seed Mix | J6: 0.16 | K6: 1590 | L6: Canteen Store Department (CSD) | M6: 254.4 | N6: CSD | O6: Indore | P6: Value Added | Q6: Seed Mix | R6: =IF(Config!$B$4>0,M6/Config!$B$4,0) | S6: =IF(Config!$B$4>0,K6/Config!$B$4,0) | T6: =R6*Config!$B$7 | U6: =S6*Config!$B$7 | V6: 0 | W6: 0 | X6: =IF(T6>0,V6/T6,0) | Y6: =IF(U6>0,W6/U6,0) | Z6: =T6-V6 | AA6: =U6-W6 | AB6: =IF(Config!$B$7>0,(V6/Config!$B$7)*Config!$B$4,0) | AC6: =IF(Config!$B$7>0,(W6/Config!$B$7)*Config!$B$4,0)
A7: May | B7: 2026 | C7: 29-04-2026 | D7: 0.47065972 | E7: Seeds_11-2541 | F7: FG | G7: Chia Seeds | H7: Premium Chia Seeds Farmley Standee Pouch 200 g | I7: Premium Chia Seeds | J7: 0.2 | K7: 1740 | L7: Canteen Store Department (CSD) | M7: 348 | N7: CSD | O7: Indore | P7: KVI | Q7: Chia Seeds | R7: =IF(Config!$B$4>0,M7/Config!$B$4,0) | S7: =IF(Config!$B$4>0,K7/Config!$B$4,0) | T7: =R7*Config!$B$7 | U7: =S7*Config!$B$7 | V7: 0 | W7: 0 | X7: =IF(T7>0,V7/T7,0) | Y7: =IF(U7>0,W7/U7,0) | Z7: =T7-V7 | AA7: =U7-W7 | AB7: =IF(Config!$B$7>0,(V7/Config!$B$7)*Config!$B$4,0) | AC7: =IF(Config!$B$7>0,(W7/Config!$B$7)*Config!$B$4,0)
A8: May | B8: 2026 | C8: 29-04-2026 | D8: 0.47065972 | E8: Multiple | F8: FG | G8: Cashew | H8: CPC | I8: Premium W320 Cashew | J8: 0.5 | K8: 116224 | L8: CPC KPKB | M8: 33831.95 | N8: CPC | O8: Multiple | P8: KVI | Q8: Cashew | R8: =IF(Config!$B$4>0,M8/Config!$B$4,0) | S8: =IF(Config!$B$4>0,K8/Config!$B$4,0) | T8: =R8*Config!$B$7 | U8: =S8*Config!$B$7 | V8: 0 | W8: 0 | X8: =IF(T8>0,V8/T8,0) | Y8: =IF(U8>0,W8/U8,0) | Z8: =T8-V8 | AA8: =U8-W8 | AB8: =IF(Config!$B$7>0,(V8/Config!$B$7)*Config!$B$4,0) | AC8: =IF(Config!$B$7>0,(W8/Config!$B$7)*Config!$B$4,0)
A9: May | B9: 2026 | C9: 29-04-2026 | D9: 0.47065972 | E9: Cashewnut_3-1987 | F9: FG | G9: Cashew | H9: Premium W320 Cashew Farmley Standee Pouch 500 g | I9: Premium W320 Cashew | J9: 0.5 | K9: 8700 | L9: CPC KPKB | M9: 4350 | N9: CPC | O9: Indore | P9: KVI | Q9: Cashew | R9: =IF(Config!$B$4>0,M9/Config!$B$4,0) | S9: =IF(Config!$B$4>0,K9/Config!$B$4,0) | T9: =R9*Config!$B$7 | U9: =S9*Config!$B$7 | V9: 0 | W9: 0 | X9: =IF(T9>0,V9/T9,0) | Y9: =IF(U9>0,W9/U9,0) | Z9: =T9-V9 | AA9: =U9-W9 | AB9: =IF(Config!$B$7>0,(V9/Config!$B$7)*Config!$B$4,0) | AC9: =IF(Config!$B$7>0,(W9/Config!$B$7)*Config!$B$4,0)
A10: May | B10: 2026 | C10: 29-04-2026 | D10: 0.47065972 | E10: Almonds_1-1748 | F10: FG | G10: Almonds | H10: Premium California Almonds Farmley Standee Pouch 500 g | I10: Premium California Almonds | J10: 0.5 | K10: 9840 | L10: CPC KPKB | M10: 4920 | N10: CPC | O10: Indore | P10: KVI | Q10: Almonds | R10: =IF(Config!$B$4>0,M10/Config!$B$4,0) | S10: =IF(Config!$B$4>0,K10/Config!$B$4,0) | T10: =R10*Config!$B$7 | U10: =S10*Config!$B$7 | V10: 0 | W10: 0 | X10: =IF(T10>0,V10/T10,0) | Y10: =IF(U10>0,W10/U10,0) | Z10: =T10-V10 | AA10: =U10-W10 | AB10: =IF(Config!$B$7>0,(V10/Config!$B$7)*Config!$B$4,0) | AC10: =IF(Config!$B$7>0,(W10/Config!$B$7)*Config!$B$4,0)
A11: May | B11: 2026 | C11: 29-04-2026 | D11: 0.47065972 | E11: Dry Fruit Mix_15-2402 | F11: FG | G11: Trail Mixes | H11: Trail Mix Farmley Standee Pouch 200 g | I11: Trail Mix | J11: 0.2 | K11: 3600 | L11: CPC KPKB | M11: 720 | N11: CPC | O11: Indore | P11: Value Added | Q11: Trail Mixes | R11: =IF(Config!$B$4>0,M11/Config!$B$4,0) | S11: =IF(Config!$B$4>0,K11/Config!$B$4,0) | T11: =R11*Config!$B$7 | U11: =S11*Config!$B$7 | V11: 0 | W11: 0 | X11: =IF(T11>0,V11/T11,0) | Y11: =IF(U11>0,W11/U11,0) | Z11: =T11-V11 | AA11: =U11-W11 | AB11: =IF(Config!$B$7>0,(V11/Config!$B$7)*Config!$B$4,0) | AC11: =IF(Config!$B$7>0,(W11/Config!$B$7)*Config!$B$4,0)
A12: May | B12: 2026 | C12: 29-04-2026 | D12: 0.47065972 | E12: Dry Fruit Mix_15-2404 | F12: FG | G12: Berry Mix | H12: Berry Mix Farmley Standee Pouch 200 g | I12: Berry Mix | J12: 0.2 | K12: 3600 | L12: CPC KPKB | M12: 720 | N12: CPC | O12: Indore | P12: Value Added | Q12: Berry Mix | R12: =IF(Config!$B$4>0,M12/Config!$B$4,0) | S12: =IF(Config!$B$4>0,K12/Config!$B$4,0) | T12: =R12*Config!$B$7 | U12: =S12*Config!$B$7 | V12: 0 | W12: 0 | X12: =IF(T12>0,V12/T12,0) | Y12: =IF(U12>0,W12/U12,0) | Z12: =T12-V12 | AA12: =U12-W12 | AB12: =IF(Config!$B$7>0,(V12/Config!$B$7)*Config!$B$4,0) | AC12: =IF(Config!$B$7>0,(W12/Config!$B$7)*Config!$B$4,0)
A13: May | B13: 2026 | C13: 29-04-2026 | D13: 0.47065972 | E13: Cashewnut_3-2472 | F13: FG | G13: Roasted & Flavoured Cashew | H13: Roasted and Salted Cashew - Farmley Standee Pouch 200 g | I13: Roasted and Salted Cashew | J13: 0.2 | K13: 4500 | L13: CPC KPKB | M13: 900 | N13: CPC | O13: Indore | P13: Value Added | Q13: Roasted & Flavoured Cashew | R13: =IF(Config!$B$4>0,M13/Config!$B$4,0) | S13: =IF(Config!$B$4>0,K13/Config!$B$4,0) | T13: =R13*Config!$B$7 | U13: =S13*Config!$B$7 | V13: 0 | W13: 0 | X13: =IF(T13>0,V13/T13,0) | Y13: =IF(U13>0,W13/U13,0) | Z13: =T13-V13 | AA13: =U13-W13 | AB13: =IF(Config!$B$7>0,(V13/Config!$B$7)*Config!$B$4,0) | AC13: =IF(Config!$B$7>0,(W13/Config!$B$7)*Config!$B$4,0)
... A31: May | B31: 2026 | C31: 29-04-2026 | D31: 0.47068287 | E31: Seeds_11-2550 | F31: FG | G31: Other Seeds | H31: Premium Flax Seeds Farmley Standee Pouch 200 g | I31: Premium Flax Seeds | J31: 0.2 | K31: 720 | L31: CPC KPKB | M31: 144 | N31: CPC | O31: Indore | P31: KVI | Q31: Other Seeds | R31: =IF(Config!$B$4>0,M31/Config!$B$4,0) | S31: =IF(Config!$B$4>0,K31/Config!$B$4,0) | T31: =R31*Config!$B$7 | U31: =S31*Config!$B$7 | V31: 0 | W31: 0 | X31: =IF(T31>0,V31/T31,0) | Y31: =IF(U31>0,W31/U31,0) | Z31: =T31-V31 | AA31: =U31-W31 | AB31: =IF(Config!$B$7>0,(V31/Config!$B$7)*Config!$B$4,0) | AC31: =IF(Config!$B$7>0,(W31/Config!$B$7)*Config!$B$4,0)
A32: May | B32: 2026 | C32: 29-04-2026 | D32: 0.47068287 | E32: Raisins_10-2382 | F32: FG | G32: Raisins | H32: Premium Munakka Farmley Standee Pouch 200 g | I32: Premium Munakka | J32: 0.2 | K32: 6150 | L32: CPC KPKB | M32: 1230 | N32: CPC | O32: Indore | P32: KVI | R32: =IF(Config!$B$4>0,M32/Config!$B$4,0) | S32: =IF(Config!$B$4>0,K32/Config!$B$4,0) | T32: =R32*Config!$B$7 | U32: =S32*Config!$B$7 | V32: 0 | W32: 0 | X32: =IF(T32>0,V32/T32,0) | Y32: =IF(U32>0,W32/U32,0) | Z32: =T32-V32 | AA32: =U32-W32 | AB32: =IF(Config!$B$7>0,(V32/Config!$B$7)*Config!$B$4,0) | AC32: =IF(Config!$B$7>0,(W32/Config!$B$7)*Config!$B$4,0)
A33: May | B33: 2026 | C33: 29-04-2026 | D33: 0.47068287 | E33: Dry Fruit Mix_15-2923 | F33: FG | G33: Trail Mixes | H33: Trail Mix Farmley Jar 450 g | I33: Trail Mix | J33: 0.45 | K33: 2064 | L33: CPC KPKB | M33: 928.8 | N33: CPC | O33: Indore | P33: Value Added | Q33: Trail Mixes | R33: =IF(Config!$B$4>0,M33/Config!$B$4,0) | S33: =IF(Config!$B$4>0,K33/Config!$B$4,0) | T33: =R33*Config!$B$7 | U33: =S33*Config!$B$7 | V33: 0 | W33: 0 | X33: =IF(T33>0,V33/T33,0) | Y33: =IF(U33>0,W33/U33,0) | Z33: =T33-V33 | AA33: =U33-W33 | AB33: =IF(Config!$B$7>0,(V33/Config!$B$7)*Config!$B$4,0) | AC33: =IF(Config!$B$7>0,(W33/Config!$B$7)*Config!$B$4,0)
A34: May | B34: 2026 | C34: 29-04-2026 | D34: 0.53008102 | E34: Multiple | F34: FG | G34: Makhana Raw | H34: Modern Trade | I34: Prasadam Makhana | J34: 0.2 | K34: 96825 | L34: 15 Customers | M34: 23848.5 | N34: Modern Trade | O34: Multiple | P34: KVI | Q34: Makhana Raw | R34: =IF(Config!$B$4>0,M34/Config!$B$4,0) | S34: =IF(Config!$B$4>0,K34/Config!$B$4,0) | T34: =R34*Config!$B$7 | U34: =S34*Config!$B$7 | V34: 9197.38 | W34: 40023 | X34: =IF(T34>0,V34/T34,0) | Y34: =IF(U34>0,W34/U34,0) | Z34: =T34-V34 | AA34: =U34-W34 | AB34: =IF(Config!$B$7>0,(V34/Config!$B$7)*Config!$B$4,0) | AC34: =IF(Config!$B$7>0,(W34/Config!$B$7)*Config!$B$4,0)
A35: May | B35: 2026 | C35: 29-04-2026 | D35: 0.53008102 | E35: Makhana_7-30098 | F35: FG | G35: Makhana Raw | H35: Prasadam Makhana Center Seal Pouch 200 g- NEW | I35: Prasadam Makhana | J35: 0.2 | K35: 3000 | L35: Metro Cash & Carry India Private Limited | M35: 600 | N35: Modern Trade | O35: Purnea | P35: KVI | Q35: Makhana Raw | R35: =IF(Config!$B$4>0,M35/Config!$B$4,0) | S35: =IF(Config!$B$4>0,K35/Config!$B$4,0) | T35: =R35*Config!$B$7 | U35: =S35*Config!$B$7 | V35: 456 | W35: 2280 | X35: =IF(T35>0,V35/T35,0) | Y35: =IF(U35>0,W35/U35,0) | Z35: =T35-V35 | AA35: =U35-W35 | AB35: =IF(Config!$B$7>0,(V35/Config!$B$7)*Config!$B$4,0) | AC35: =IF(Config!$B$7>0,(W35/Config!$B$7)*Config!$B$4,0)
A36: May | B36: 2026 | C36: 29-04-2026 | D36: 0.53008102 | E36: Dry Fruit Mix_15-2800 | F36: FG | G36: Trail Mixes | H36: Premium Panchmeva Farmley Jar 425 g- Institutional | I36: Premium Panchmewa Superfood | J36: 0.425 | K36: 4500 | L36: Metro Cash & Carry India Private Limited | M36: 1912.5 | N36: Modern Trade | O36: Indore | P36: Value Added | Q36: Trail Mixes | R36: =IF(Config!$B$4>0,M36/Config!$B$4,0) | S36: =IF(Config!$B$4>0,K36/Config!$B$4,0) | T36: =R36*Config!$B$7 | U36: =S36*Config!$B$7 | V36: 40.8 | W36: 96 | X36: =IF(T36>0,V36/T36,0) | Y36: =IF(U36>0,W36/U36,0) | Z36: =T36-V36 | AA36: =U36-W36 | AB36: =IF(Config!$B$7>0,(V36/Config!$B$7)*Config!$B$4,0) | AC36: =IF(Config!$B$7>0,(W36/Config!$B$7)*Config!$B$4,0)
A37: May | B37: 2026 | C37: 29-04-2026 | D37: 0.53008102 | E37: Almonds_1-196 | F37: FG | G37: Almonds | H37: Popular California Almonds Farmley Standee Pouch 1 kg | I37: Popular California Almonds | J37: 1 | K37: 400 | L37: Metro Cash & Carry India Private Limited | M37: 400 | N37: Modern Trade | O37: Indore | P37: KVI | Q37: Almonds | R37: =IF(Config!$B$4>0,M37/Config!$B$4,0) | S37: =IF(Config!$B$4>0,K37/Config!$B$4,0) | T37: =R37*Config!$B$7 | U37: =S37*Config!$B$7 | V37: 312 | W37: 312 | X37: =IF(T37>0,V37/T37,0) | Y37: =IF(U37>0,W37/U37,0) | Z37: =T37-V37 | AA37: =U37-W37 | AB37: =IF(Config!$B$7>0,(V37/Config!$B$7)*Config!$B$4,0) | AC37: =IF(Config!$B$7>0,(W37/Config!$B$7)*Config!$B$4,0)
A38: May | B38: 2026 | C38: 29-04-2026 | D38: 0.53008102 | E38: Almonds_1-1750 | F38: FG | G38: Almonds | H38: Popular California Almonds Farmley Standee Pouch 500 g | I38: Popular California Almonds | J38: 0.5 | K38: 1500 | L38: Metro Cash & Carry India Private Limited | M38: 750 | N38: Modern Trade | O38: Indore | P38: KVI | Q38: Almonds | R38: =IF(Config!$B$4>0,M38/Config!$B$4,0) | S38: =IF(Config!$B$4>0,K38/Config!$B$4,0) | T38: =R38*Config!$B$7 | U38: =S38*Config!$B$7 | V38: 392 | W38: 784 | X38: =IF(T38>0,V38/T38,0) | Y38: =IF(U38>0,W38/U38,0) | Z38: =T38-V38 | AA38: =U38-W38 | AB38: =IF(Config!$B$7>0,(V38/Config!$B$7)*Config!$B$4,0) | AC38: =IF(Config!$B$7>0,(W38/Config!$B$7)*Config!$B$4,0)
A39: May | B39: 2026 | C39: 29-04-2026 | D39: 0.53008102 | E39: Makhana_7-30096 | F39: FG | G39: Makhana Raw | H39: Prasadam Makhana Center Seal Pouch 100 g- NEW | I39: Prasadam Makhana | J39: 0.1 | K39: 800 | L39: Metro Cash & Carry India Private Limited | M39: 80 | N39: Modern Trade | O39: Purnea | P39: KVI | Q39: Makhana Raw | R39: =IF(Config!$B$4>0,M39/Config!$B$4,0) | S39: =IF(Config!$B$4>0,K39/Config!$B$4,0) | T39: =R39*Config!$B$7 | U39: =S39*Config!$B$7 | V39: 136 | W39: 1360 | X39: =IF(T39>0,V39/T39,0) | Y39: =IF(U39>0,W39/U39,0) | Z39: =T39-V39 | AA39: =U39-W39 | AB39: =IF(Config!$B$7>0,(V39/Config!$B$7)*Config!$B$4,0) | AC39: =IF(Config!$B$7>0,(W39/Config!$B$7)*Config!$B$4,0)
A40: May | B40: 2026 | C40: 29-04-2026 | D40: 0.53008102 | E40: Seeds_11-2541 | F40: FG | G40: Chia Seeds | H40: Premium Chia Seeds Farmley Standee Pouch 200 g | I40: Premium Chia Seeds | J40: 0.2 | K40: 4000 | L40: Metro Cash & Carry India Private Limited | M40: 800 | N40: Modern Trade | O40: Indore | P40: KVI | Q40: Chia Seeds | R40: =IF(Config!$B$4>0,M40/Config!$B$4,0) | S40: =IF(Config!$B$4>0,K40/Config!$B$4,0) | T40: =R40*Config!$B$7 | U40: =S40*Config!$B$7 | V40: 390 | W40: 1950 | X40: =IF(T40>0,V40/T40,0) | Y40: =IF(U40>0,W40/U40,0) | Z40: =T40-V40 | AA40: =U40-W40 | AB40: =IF(Config!$B$7>0,(V40/Config!$B$7)*Config!$B$4,0) | AC40: =IF(Config!$B$7>0,(W40/Config!$B$7)*Config!$B$4,0)
A41: May | B41: 2026 | C41: 29-04-2026 | D41: 0.53009259 | E41: Dates_4-2469 | F41: FG | G41: Dates | H41: Premium Omani Fard Dates Farmley standee pouch 400 g | I41: Premium Fard Dates | J41: 0.4 | K41: 2800 | L41: Metro Cash & Carry India Private Limited | M41: 1120 | N41: Modern Trade | O41: Indore | P41: KVI | Q41: Dates | R41: =IF(Config!$B$4>0,M41/Config!$B$4,0) | S41: =IF(Config!$B$4>0,K41/Config!$B$4,0) | T41: =R41*Config!$B$7 | U41: =S41*Config!$B$7 | V41: 828 | W41: 2070 | X41: =IF(T41>0,V41/T41,0) | Y41: =IF(U41>0,W41/U41,0) | Z41: =T41-V41 | AA41: =U41-W41 | AB41: =IF(Config!$B$7>0,(V41/Config!$B$7)*Config!$B$4,0) | AC41: =IF(Config!$B$7>0,(W41/Config!$B$7)*Config!$B$4,0)
A42: May | B42: 2026 | C42: 29-04-2026 | D42: 0.53009259 | E42: Dry Fruit Mix_15-2403 | F42: FG | G42: Seed Mix | H42: Seed Mix Farmley Standee Pouch 200 g | I42: Seed Mix | J42: 0.2 | K42: 1000 | L42: Metro Cash & Carry India Private Limited | M42: 200 | N42: Modern Trade | O42: Indore | P42: Value Added | Q42: Seed Mix | R42: =IF(Config!$B$4>0,M42/Config!$B$4,0) | S42: =IF(Config!$B$4>0,K42/Config!$B$4,0) | T42: =R42*Config!$B$7 | U42: =S42*Config!$B$7 | V42: 72 | W42: 360 | X42: =IF(T42>0,V42/T42,0) | Y42: =IF(U42>0,W42/U42,0) | Z42: =T42-V42 | AA42: =U42-W42 | AB42: =IF(Config!$B$7>0,(V42/Config!$B$7)*Config!$B$4,0) | AC42: =IF(Config!$B$7>0,(W42/Config!$B$7)*Config!$B$4,0)
A43: May | B43: 2026 | C43: 29-04-2026 | D43: 0.53009259 | E43: Dry Fruit Mix_15-2404 | F43: FG | G43: Berry Mix | H43: Berry Mix Farmley Standee Pouch 200 g | I43: Berry Mix | J43: 0.2 | K43: 1600 | L43: Metro Cash & Carry India Private Limited | M43: 320 | N43: Modern Trade | O43: Indore | P43: Value Added | Q43: Berry Mix | R43: =IF(Config!$B$4>0,M43/Config!$B$4,0) | S43: =IF(Config!$B$4>0,K43/Config!$B$4,0) | T43: =R43*Config!$B$7 | U43: =S43*Config!$B$7 | V43: 126 | W43: 630 | X43: =IF(T43>0,V43/T43,0) | Y43: =IF(U43>0,W43/U43,0) | Z43: =T43-V43 | AA43: =U43-W43 | AB43: =IF(Config!$B$7>0,(V43/Config!$B$7)*Config!$B$4,0) | AC43: =IF(Config!$B$7>0,(W43/Config!$B$7)*Config!$B$4,0)
A44: May | B44: 2026 | C44: 29-04-2026 | D44: 0.53009259 | E44: Dry Fruit Mix_15-2402 | F44: FG | G44: Trail Mixes | H44: Trail Mix Farmley Standee Pouch 200 g | I44: Trail Mix | J44: 0.2 | K44: 800 | L44: Metro Cash & Carry India Private Limited | M44: 160 | N44: Modern Trade | O44: Indore | P44: Value Added | Q44: Trail Mixes | R44: =IF(Config!$B$4>0,M44/Config!$B$4,0) | S44: =IF(Config!$B$4>0,K44/Config!$B$4,0) | T44: =R44*Config!$B$7 | U44: =S44*Config!$B$7 | V44: 132 | W44: 660 | X44: =IF(T44>0,V44/T44,0) | Y44: =IF(U44>0,W44/U44,0) | Z44: =T44-V44 | AA44: =U44-W44 | AB44: =IF(Config!$B$7>0,(V44/Config!$B$7)*Config!$B$4,0) | AC44: =IF(Config!$B$7>0,(W44/Config!$B$7)*Config!$B$4,0)
... A56: May | B56: 2026 | C56: 29-04-2026 | D56: 0.53010417 | E56: Dates_4-20162 | F56: FG | G56: Healthy Desserts | H56: Coffee Rush Date Bite Farmley Tin Jar 200g | I56: Coffee Date Bites | J56: 0.2 | K56: 1000 | L56: Metro Cash & Carry India Private Limited | M56: 200 | N56: Modern Trade | O56: Indore | P56: Value Added | Q56: Healthy Desserts | R56: =IF(Config!$B$4>0,M56/Config!$B$4,0) | S56: =IF(Config!$B$4>0,K56/Config!$B$4,0) | T56: =R56*Config!$B$7 | U56: =S56*Config!$B$7 | V56: 0 | W56: 0 | X56: =IF(T56>0,V56/T56,0) | Y56: =IF(U56>0,W56/U56,0) | Z56: =T56-V56 | AA56: =U56-W56 | AB56: =IF(Config!$B$7>0,(V56/Config!$B$7)*Config!$B$4,0) | AC56: =IF(Config!$B$7>0,(W56/Config!$B$7)*Config!$B$4,0)
A57: May | B57: 2026 | C57: 30-04-2026 | D57: 0.69038194 | E57: Dates_4-20173 | F57: FG | G57: Healthy Desserts | H57: Dark Choco-Orange Date Bite Farmley Monocarton 360g -Pack of 6 (60g each)- with SRP | I57: Date bites choco-Orange | J57: 0.36 | K57: 167 | L57: Metro Cash & Carry India Private Limited | M57: 60.12 | N57: Modern Trade | O57: Indore | P57: Value Added | R57: =IF(Config!$B$4>0,M57/Config!$B$4,0) | S57: =IF(Config!$B$4>0,K57/Config!$B$4,0) | T57: =R57*Config!$B$7 | U57: =S57*Config!$B$7 | V57: 0 | W57: 0 | X57: =IF(T57>0,V57/T57,0) | Y57: =IF(U57>0,W57/U57,0) | Z57: =T57-V57 | AA57: =U57-W57 | AB57: =IF(Config!$B$7>0,(V57/Config!$B$7)*Config!$B$4,0) | AC57: =IF(Config!$B$7>0,(W57/Config!$B$7)*Config!$B$4,0)
A58: May | B58: 2026 | C58: 30-04-2026 | D58: 0.69038194 | E58: Dates_4-20174 | F58: FG | G58: Healthy Desserts | H58: Classic Date Bite Farmley Monocarton 360g- Pack of 6 (60g each)- With SRP | I58: Classic Date bites | J58: 0.36 | K58: 333 | L58: Metro Cash & Carry India Private Limited | M58: 119.88 | N58: Modern Trade | O58: Indore | P58: Value Added | Q58: Healthy Desserts | R58: =IF(Config!$B$4>0,M58/Config!$B$4,0) | S58: =IF(Config!$B$4>0,K58/Config!$B$4,0) | T58: =R58*Config!$B$7 | U58: =S58*Config!$B$7 | V58: 0 | W58: 0 | X58: =IF(T58>0,V58/T58,0) | Y58: =IF(U58>0,W58/U58,0) | Z58: =T58-V58 | AA58: =U58-W58 | AB58: =IF(Config!$B$7>0,(V58/Config!$B$7)*Config!$B$4,0) | AC58: =IF(Config!$B$7>0,(W58/Config!$B$7)*Config!$B$4,0)
A59: May | B59: 2026 | C59: 25-04-2026 | D59: 0.7266088 | E59: Dry Fruit Mix_15-2402 | F59: FG | G59: Trail Mixes | H59: Trail Mix Farmley Standee Pouch 200 g | I59: Trail Mix | J59: 0.2 | K59: 100 | L59: Wal-Mart India Private Limited | M59: 20 | N59: Modern Trade | O59: Indore | P59: Value Added | Q59: Trail Mixes | R59: =IF(Config!$B$4>0,M59/Config!$B$4,0) | S59: =IF(Config!$B$4>0,K59/Config!$B$4,0) | T59: =R59*Config!$B$7 | U59: =S59*Config!$B$7 | V59: 6 | W59: 30 | X59: =IF(T59>0,V59/T59,0) | Y59: =IF(U59>0,W59/U59,0) | Z59: =T59-V59 | AA59: =U59-W59 | AB59: =IF(Config!$B$7>0,(V59/Config!$B$7)*Config!$B$4,0) | AC59: =IF(Config!$B$7>0,(W59/Config!$B$7)*Config!$B$4,0)
A60: May | B60: 2026 | C60: 25-04-2026 | D60: 0.7266088 | E60: Dry Fruit Mix_15-2403 | F60: FG | G60: Seed Mix | H60: Seed Mix Farmley Standee Pouch 200 g | I60: Seed Mix | J60: 0.2 | K60: 150 | L60: Wal-Mart India Private Limited | M60: 30 | N60: Modern Trade | O60: Indore | P60: Value Added | Q60: Seed Mix | R60: =IF(Config!$B$4>0,M60/Config!$B$4,0) | S60: =IF(Config!$B$4>0,K60/Config!$B$4,0) | T60: =R60*Config!$B$7 | U60: =S60*Config!$B$7 | V60: 24 | W60: 120 | X60: =IF(T60>0,V60/T60,0) | Y60: =IF(U60>0,W60/U60,0) | Z60: =T60-V60 | AA60: =U60-W60 | AB60: =IF(Config!$B$7>0,(V60/Config!$B$7)*Config!$B$4,0) | AC60: =IF(Config!$B$7>0,(W60/Config!$B$7)*Config!$B$4,0)
A61: May | B61: 2026 | C61: 25-04-2026 | D61: 0.7266088 | E61: Dry Fruit Mix_15-2404 | F61: FG | G61: Berry Mix | H61: Berry Mix Farmley Standee Pouch 200 g | I61: Berry Mix | J61: 0.2 | K61: 400 | L61: Wal-Mart India Private Limited | M61: 80 | N61: Modern Trade | O61: Indore | P61: Value Added | Q61: Berry Mix | R61: =IF(Config!$B$4>0,M61/Config!$B$4,0) | S61: =IF(Config!$B$4>0,K61/Config!$B$4,0) | T61: =R61*Config!$B$7 | U61: =S61*Config!$B$7 | V61: 36 | W61: 180 | X61: =IF(T61>0,V61/T61,0) | Y61: =IF(U61>0,W61/U61,0) | Z61: =T61-V61 | AA61: =U61-W61 | AB61: =IF(Config!$B$7>0,(V61/Config!$B$7)*Config!$B$4,0) | AC61: =IF(Config!$B$7>0,(W61/Config!$B$7)*Config!$B$4,0)
A62: May | B62: 2026 | C62: 25-04-2026 | D62: 0.7266088 | E62: Walnut_12-1535 | F62: FG | G62: Walnut | H62: Premium Broken Walnut Kernels Farmley Standee Pouch 200 g | I62: Premium Broken Walnut Kernels | J62: 0.2 | K62: 200 | L62: Wal-Mart India Private Limited | M62: 40 | N62: Modern Trade | O62: Indore | P62: KVI | Q62: Walnut | R62: =IF(Config!$B$4>0,M62/Config!$B$4,0) | S62: =IF(Config!$B$4>0,K62/Config!$B$4,0) | T62: =R62*Config!$B$7 | U62: =S62*Config!$B$7 | V62: 19.2 | W62: 96 | X62: =IF(T62>0,V62/T62,0) | Y62: =IF(U62>0,W62/U62,0) | Z62: =T62-V62 | AA62: =U62-W62 | AB62: =IF(Config!$B$7>0,(V62/Config!$B$7)*Config!$B$4,0) | AC62: =IF(Config!$B$7>0,(W62/Config!$B$7)*Config!$B$4,0)
A63: May | B63: 2026 | C63: 25-04-2026 | D63: 0.7266088 | E63: Fig_6-2464 | F63: FG | G63: Figs | H63: Premium Anjeer Farmley Standee Pouch 200 g | I63: Premium Anjeer | J63: 0.2 | K63: 300 | L63: Wal-Mart India Private Limited | M63: 60 | N63: Modern Trade | O63: Indore | P63: KVI | Q63: Figs | R63: =IF(Config!$B$4>0,M63/Config!$B$4,0) | S63: =IF(Config!$B$4>0,K63/Config!$B$4,0) | T63: =R63*Config!$B$7 | U63: =S63*Config!$B$7 | V63: 30 | W63: 150 | X63: =IF(T63>0,V63/T63,0) | Y63: =IF(U63>0,W63/U63,0) | Z63: =T63-V63 | AA63: =U63-W63 | AB63: =IF(Config!$B$7>0,(V63/Config!$B$7)*Config!$B$4,0) | AC63: =IF(Config!$B$7>0,(W63/Config!$B$7)*Config!$B$4,0)
A64: May | B64: 2026 | C64: 25-04-2026 | D64: 0.7266088 | E64: Dates_4-2469 | F64: FG | G64: Dates | H64: Premium Omani Fard Dates Farmley standee pouch 400 g | I64: Premium Fard Dates | J64: 0.4 | K64: 1100 | L64: Wal-Mart India Private Limited | M64: 440 | N64: Modern Trade | O64: Indore | P64: KVI | Q64: Dates | R64: =IF(Config!$B$4>0,M64/Config!$B$4,0) | S64: =IF(Config!$B$4>0,K64/Config!$B$4,0) | T64: =R64*Config!$B$7 | U64: =S64*Config!$B$7 | V64: 0 | W64: 0 | X64: =IF(T64>0,V64/T64,0) | Y64: =IF(U64>0,W64/U64,0) | Z64: =T64-V64 | AA64: =U64-W64 | AB64: =IF(Config!$B$7>0,(V64/Config!$B$7)*Config!$B$4,0) | AC64: =IF(Config!$B$7>0,(W64/Config!$B$7)*Config!$B$4,0)
A65: May | B65: 2026 | C65: 25-04-2026 | D65: 0.7266088 | E65: Dry Fruit Mix_15-2800 | F65: FG | G65: Trail Mixes | H65: Premium Panchmeva Farmley Jar 425 g- Institutional | I65: Premium Panchmewa Superfood | J65: 0.425 | K65: 200 | L65: Wal-Mart India Private Limited | M65: 85 | N65: Modern Trade | O65: Indore | P65: Value Added | Q65: Trail Mixes | R65: =IF(Config!$B$4>0,M65/Config!$B$4,0) | S65: =IF(Config!$B$4>0,K65/Config!$B$4,0) | T65: =R65*Config!$B$7 | U65: =S65*Config!$B$7 | V65: 61.2 | W65: 144 | X65: =IF(T65>0,V65/T65,0) | Y65: =IF(U65>0,W65/U65,0) | Z65: =T65-V65 | AA65: =U65-W65 | AB65: =IF(Config!$B$7>0,(V65/Config!$B$7)*Config!$B$4,0) | AC65: =IF(Config!$B$7>0,(W65/Config!$B$7)*Config!$B$4,0)
A66: May | B66: 2026 | C66: 25-04-2026 | D66: 0.7266088 | E66: Cashewnut_3-1987 | F66: FG | G66: Cashew | H66: Premium W320 Cashew Farmley Standee Pouch 500 g | I66: Premium W320 Cashew | J66: 0.5 | K66: 100 | L66: Wal-Mart India Private Limited | M66: 50 | N66: Modern Trade | O66: Udupi | P66: KVI | Q66: Cashew | R66: =IF(Config!$B$4>0,M66/Config!$B$4,0) | S66: =IF(Config!$B$4>0,K66/Config!$B$4,0) | T66: =R66*Config!$B$7 | U66: =S66*Config!$B$7 | V66: 100 | W66: 200 | X66: =IF(T66>0,V66/T66,0) | Y66: =IF(U66>0,W66/U66,0) | Z66: =T66-V66 | AA66: =U66-W66 | AB66: =IF(Config!$B$7>0,(V66/Config!$B$7)*Config!$B$4,0) | AC66: =IF(Config!$B$7>0,(W66/Config!$B$7)*Config!$B$4,0)
A67: May | B67: 2026 | C67: 25-04-2026 | D67: 0.7266088 | E67: Makhana_7-30098 | F67: FG | G67: Makhana Raw | H67: Prasadam Makhana Center Seal Pouch 200 g- NEW | I67: Prasadam Makhana | J67: 0.2 | K67: 400 | L67: Wal-Mart India Private Limited | M67: 80 | N67: Modern Trade | O67: Purnea | P67: KVI | Q67: Makhana Raw | R67: =IF(Config!$B$4>0,M67/Config!$B$4,0) | S67: =IF(Config!$B$4>0,K67/Config!$B$4,0) | T67: =R67*Config!$B$7 | U67: =S67*Config!$B$7 | V67: 48 | W67: 240 | X67: =IF(T67>0,V67/T67,0) | Y67: =IF(U67>0,W67/U67,0) | Z67: =T67-V67 | AA67: =U67-W67 | AB67: =IF(Config!$B$7>0,(V67/Config!$B$7)*Config!$B$4,0) | AC67: =IF(Config!$B$7>0,(W67/Config!$B$7)*Config!$B$4,0)
A68: May | B68: 2026 | C68: 25-04-2026 | D68: 0.72662037 | E68: Seeds_11-2541 | F68: FG | G68: Chia Seeds | H68: Premium Chia Seeds Farmley Standee Pouch 200 g | I68: Premium Chia Seeds | J68: 0.2 | K68: 1000 | L68: Wal-Mart India Private Limited | M68: 200 | N68: Modern Trade | O68: Indore | P68: KVI | Q68: Chia Seeds | R68: =IF(Config!$B$4>0,M68/Config!$B$4,0) | S68: =IF(Config!$B$4>0,K68/Config!$B$4,0) | T68: =R68*Config!$B$7 | U68: =S68*Config!$B$7 | V68: 174 | W68: 870 | X68: =IF(T68>0,V68/T68,0) | Y68: =IF(U68>0,W68/U68,0) | Z68: =T68-V68 | AA68: =U68-W68 | AB68: =IF(Config!$B$7>0,(V68/Config!$B$7)*Config!$B$4,0) | AC68: =IF(Config!$B$7>0,(W68/Config!$B$7)*Config!$B$4,0)
...

Sheet RunRate by Origin
A1: Month | B1: Year | C1: Last Modified Date | D1: Last Modified Time | E1: Item Code | F1: BOM Item Type | G1: Item Group | H1: Item Name | I1: Item Parent | J1: Conversion Factor | K1: Projection Units | L1: Customer | M1: Total KGs | N1: Customer Group | O1: Origin | P1: Item Type | Q1: New MIS Item Group | R1: Daily Demand(Total KGs) | S1: Daily Demand(Projection Units) | T1: Projected KGs as of period | U1: Projected Units as of period | V1: Actual SO KGs | W1: Actual SO Units | X1: Achievement % KGs | Y1: Achievement % Units | Z1: Diff Proj-SO KGs | AA1: Diff Proj-SO Units | AB1: Run Rate Month-End KGs | AC1: Run Rate Month-End Units
A2: May | B2: 2026 | C2: 29-04-2026 | D2: 0.47064815 | E2: Multiple | F2: FG | G2: Roasted & Flavoured Makhana | H2: Purnea | I2: Prasadam Roasted Makhana | J2: 0.083 | K2: 1736945 | L2: 75 Customers | M2: 93669.05 | N2: Multiple | O2: Purnea | P2: Value Added | Q2: Roasted & Flavoured Makhana | R2: =IF(Config!$B$4>0,M2/Config!$B$4,0) | S2: =IF(Config!$B$4>0,K2/Config!$B$4,0) | T2: =R2*Config!$B$7 | U2: =S2*Config!$B$7 | V2: 45055.85 | W2: 902419 | X2: =IF(T2>0,V2/T2,0) | Y2: =IF(U2>0,W2/U2,0) | Z2: =T2-V2 | AA2: =U2-W2 | AB2: =IF(Config!$B$7>0,(V2/Config!$B$7)*Config!$B$4,0) | AC2: =IF(Config!$B$7>0,(W2/Config!$B$7)*Config!$B$4,0)
A3: May | B3: 2026 | C3: 29-04-2026 | D3: 0.47064815 | E3: Makhana_7-30163 | F3: FG | G3: Roasted & Flavoured Makhana | H3: Roasted & Flavored Makhana - Tangy Tomato Farmley Composite Jar 83 g | I3: Prasadam Roasted Makhana | J3: 0.083 | K3: 2904 | L3: Canteen Store Department (CSD) | M3: 241.03 | N3: CSD | O3: Purnea | P3: Value Added | Q3: Roasted & Flavoured Makhana | R3: =IF(Config!$B$4>0,M3/Config!$B$4,0) | S3: =IF(Config!$B$4>0,K3/Config!$B$4,0) | T3: =R3*Config!$B$7 | U3: =S3*Config!$B$7 | V3: 0 | W3: 0 | X3: =IF(T3>0,V3/T3,0) | Y3: =IF(U3>0,W3/U3,0) | Z3: =T3-V3 | AA3: =U3-W3 | AB3: =IF(Config!$B$7>0,(V3/Config!$B$7)*Config!$B$4,0) | AC3: =IF(Config!$B$7>0,(W3/Config!$B$7)*Config!$B$4,0)
A4: May | B4: 2026 | C4: 29-04-2026 | D4: 0.47065972 | E4: Makhana_7-30166 | F4: FG | G4: Roasted & Flavoured Makhana | H4: Roasted & Flavored Makhana - Mint Farmley Composite Jar 83 g | I4: Prasadam Roasted Makhana | J4: 0.083 | K4: 2736 | L4: Canteen Store Department (CSD) | M4: 227.09 | N4: CSD | O4: Purnea | P4: Value Added | Q4: Roasted & Flavoured Makhana | R4: =IF(Config!$B$4>0,M4/Config!$B$4,0) | S4: =IF(Config!$B$4>0,K4/Config!$B$4,0) | T4: =R4*Config!$B$7 | U4: =S4*Config!$B$7 | V4: 0 | W4: 0 | X4: =IF(T4>0,V4/T4,0) | Y4: =IF(U4>0,W4/U4,0) | Z4: =T4-V4 | AA4: =U4-W4 | AB4: =IF(Config!$B$7>0,(V4/Config!$B$7)*Config!$B$4,0) | AC4: =IF(Config!$B$7>0,(W4/Config!$B$7)*Config!$B$4,0)
A5: May | B5: 2026 | C5: 29-04-2026 | D5: 0.47065972 | E5: Makhana_7-30167 | F5: FG | G5: Roasted & Flavoured Makhana | H5: Roasted & Salted Makhana Farmley Composite Jar 83 g | I5: Prasadam Roasted Makhana | J5: 0.083 | K5: 2448 | L5: Canteen Store Department (CSD) | M5: 203.18 | N5: CSD | O5: Purnea | P5: Value Added | Q5: Roasted & Flavoured Makhana | R5: =IF(Config!$B$4>0,M5/Config!$B$4,0) | S5: =IF(Config!$B$4>0,K5/Config!$B$4,0) | T5: =R5*Config!$B$7 | U5: =S5*Config!$B$7 | V5: 0 | W5: 0 | X5: =IF(T5>0,V5/T5,0) | Y5: =IF(U5>0,W5/U5,0) | Z5: =T5-V5 | AA5: =U5-W5 | AB5: =IF(Config!$B$7>0,(V5/Config!$B$7)*Config!$B$4,0) | AC5: =IF(Config!$B$7>0,(W5/Config!$B$7)*Config!$B$4,0)
A6: May | B6: 2026 | C6: 29-04-2026 | D6: 0.4706713 | E6: Makhana_7-30098 | F6: FG | G6: Makhana Raw | H6: Prasadam Makhana Center Seal Pouch 200 g- NEW | I6: Prasadam Makhana | J6: 0.2 | K6: 7000 | L6: CPC KPKB | M6: 1400 | N6: CPC | O6: Purnea | P6: KVI | Q6: Makhana Raw | R6: =IF(Config!$B$4>0,M6/Config!$B$4,0) | S6: =IF(Config!$B$4>0,K6/Config!$B$4,0) | T6: =R6*Config!$B$7 | U6: =S6*Config!$B$7 | V6: 0 | W6: 0 | X6: =IF(T6>0,V6/T6,0) | Y6: =IF(U6>0,W6/U6,0) | Z6: =T6-V6 | AA6: =U6-W6 | AB6: =IF(Config!$B$7>0,(V6/Config!$B$7)*Config!$B$4,0) | AC6: =IF(Config!$B$7>0,(W6/Config!$B$7)*Config!$B$4,0)
A7: May | B7: 2026 | C7: 29-04-2026 | D7: 0.4706713 | E7: Makhana_7-30096 | F7: FG | G7: Makhana Raw | H7: Prasadam Makhana Center Seal Pouch 100 g- NEW | I7: Prasadam Makhana | J7: 0.1 | K7: 9600 | L7: CPC KPKB | M7: 960 | N7: CPC | O7: Purnea | P7: KVI | Q7: Makhana Raw | R7: =IF(Config!$B$4>0,M7/Config!$B$4,0) | S7: =IF(Config!$B$4>0,K7/Config!$B$4,0) | T7: =R7*Config!$B$7 | U7: =S7*Config!$B$7 | V7: 0 | W7: 0 | X7: =IF(T7>0,V7/T7,0) | Y7: =IF(U7>0,W7/U7,0) | Z7: =T7-V7 | AA7: =U7-W7 | AB7: =IF(Config!$B$7>0,(V7/Config!$B$7)*Config!$B$4,0) | AC7: =IF(Config!$B$7>0,(W7/Config!$B$7)*Config!$B$4,0)
A8: May | B8: 2026 | C8: 29-04-2026 | D8: 0.4706713 | E8: Makhana_7-2995 | F8: FG | G8: Roasted & Flavoured Makhana | H8: Roasted & Flavoured Cream & Onion Makhana Farmley Jar 55 g | I8: Prasadam Roasted Makhana | J8: 0.055 | K8: 1050 | L8: CPC KPKB | M8: 57.75 | N8: CPC | O8: Purnea | P8: Value Added | Q8: Roasted & Flavoured Makhana | R8: =IF(Config!$B$4>0,M8/Config!$B$4,0) | S8: =IF(Config!$B$4>0,K8/Config!$B$4,0) | T8: =R8*Config!$B$7 | U8: =S8*Config!$B$7 | V8: 0 | W8: 0 | X8: =IF(T8>0,V8/T8,0) | Y8: =IF(U8>0,W8/U8,0) | Z8: =T8-V8 | AA8: =U8-W8 | AB8: =IF(Config!$B$7>0,(V8/Config!$B$7)*Config!$B$4,0) | AC8: =IF(Config!$B$7>0,(W8/Config!$B$7)*Config!$B$4,0)
